[2024-10-14T21:27:26.455+0000] {taskinstance.py:1956} INFO - Dependencies all met for dep_context=non-requeueable deps ti=<TaskInstance: dag_get_weather_data.fetch_tranform_data.fetch_and_save_weather scheduled__2024-10-14T20:00:00+00:00 [queued]>
[2024-10-14T21:27:26.467+0000] {taskinstance.py:1956} INFO - Dependencies all met for dep_context=requeueable deps ti=<TaskInstance: dag_get_weather_data.fetch_tranform_data.fetch_and_save_weather scheduled__2024-10-14T20:00:00+00:00 [queued]>
[2024-10-14T21:27:26.467+0000] {taskinstance.py:2170} INFO - Starting attempt 2 of 2
[2024-10-14T21:27:26.481+0000] {taskinstance.py:2191} INFO - Executing <Task(_PythonDecoratedOperator): fetch_tranform_data.fetch_and_save_weather> on 2024-10-14 20:00:00+00:00
[2024-10-14T21:27:26.496+0000] {standard_task_runner.py:60} INFO - Started process 446 to run task
[2024-10-14T21:27:26.501+0000] {standard_task_runner.py:87} INFO - Running: ['***', 'tasks', 'run', 'dag_get_weather_data', 'fetch_tranform_data.fetch_and_save_weather', 'scheduled__2024-10-14T20:00:00+00:00', '--job-id', '7', '--raw', '--subdir', 'DAGS_FOLDER/dag_get_weather.py', '--cfg-path', '/tmp/tmpqm4g2mmk']
[2024-10-14T21:27:26.503+0000] {standard_task_runner.py:88} INFO - Job 7: Subtask fetch_tranform_data.fetch_and_save_weather
[2024-10-14T21:27:26.522+0000] {warnings.py:109} WARNING - /home/***/.local/lib/python3.8/site-packages/***/settings.py:194: DeprecationWarning: The sql_alchemy_conn option in [core] has been moved to the sql_alchemy_conn option in [database] - the old setting has been used, but please update your config.
  SQL_ALCHEMY_CONN = conf.get("database", "SQL_ALCHEMY_CONN")

[2024-10-14T21:27:26.556+0000] {task_command.py:423} INFO - Running <TaskInstance: dag_get_weather_data.fetch_tranform_data.fetch_and_save_weather scheduled__2024-10-14T20:00:00+00:00 [running]> on host cc88bfa9cc01
[2024-10-14T21:27:26.649+0000] {taskinstance.py:2480} INFO - Exporting env vars: AIRFLOW_CTX_DAG_OWNER='***' AIRFLOW_CTX_DAG_ID='dag_get_weather_data' AIRFLOW_CTX_TASK_ID='fetch_tranform_data.fetch_and_save_weather' AIRFLOW_CTX_EXECUTION_DATE='2024-10-14T20:00:00+00:00' AIRFLOW_CTX_TRY_NUMBER='2' AIRFLOW_CTX_DAG_RUN_ID='scheduled__2024-10-14T20:00:00+00:00'
[2024-10-14T21:27:26.651+0000] {taskinstance.py:2698} ERROR - Task failed with exception
Traceback (most recent call last):
  File "/home/airflow/.local/lib/python3.8/site-packages/airflow/models/taskinstance.py", line 433, in _execute_task
    result = execute_callable(context=context, **execute_callable_kwargs)
  File "/home/airflow/.local/lib/python3.8/site-packages/airflow/decorators/base.py", line 241, in execute
    return_value = super().execute(context)
  File "/home/airflow/.local/lib/python3.8/site-packages/airflow/operators/python.py", line 199, in execute
    return_value = self.execute_callable()
  File "/home/airflow/.local/lib/python3.8/site-packages/airflow/operators/python.py", line 216, in execute_callable
    return self.python_callable(*self.op_args, **self.op_kwargs)
  File "/opt/airflow/dags/dag_get_weather.py", line 58, in fetch_and_save_weather
    data = kwargs['data']
KeyError: 'data'
[2024-10-14T21:27:26.660+0000] {taskinstance.py:1138} INFO - Marking task as FAILED. dag_id=dag_get_weather_data, task_id=fetch_tranform_data.fetch_and_save_weather, execution_date=20241014T200000, start_date=20241014T212726, end_date=20241014T212726
[2024-10-14T21:27:26.683+0000] {standard_task_runner.py:107} ERROR - Failed to execute job 7 for task fetch_tranform_data.fetch_and_save_weather ('data'; 446)
[2024-10-14T21:27:26.713+0000] {local_task_job_runner.py:234} INFO - Task exited with return code 1
[2024-10-14T21:27:26.758+0000] {taskinstance.py:3280} INFO - 0 downstream tasks scheduled from follow-on schedule check
